Workbook

Sheet Dashboard
A1: Hastings Family Texas Draw Planner 2026-2027 — Statewide V4
A2: Statewide deer database added: use Master Hunt List to apply and track every verified TPWD deer opportunity.
A3: Metric | B3: Formula | C3: Value | E3: Quick Links | F3: Sheet
A4: Total hunt/application rows | B4: =COUNTA('Master Hunt List'!D:D)-1 -> 294 | E4: Start here | F4: Best Bets
A5: Youth opportunities | B5: =COUNTIF('Master Hunt List'!H:H,"Yes") -> 283 | E5: Full tracker | F5: Master Hunt List
A6: Core/DFW hunts <=400 miles | B6: =COUNTIFS('Master Hunt List'!P:P,"<=400") -> 78 | E6: Youth only | F6: Youth Priority
A7: Stretch hunts >400 miles | B7: =COUNTIFS('Master Hunt List'!P:P,">400") -> 215 | E7: Calendar | F7: Application Calendar
A8: Applied rows marked Yes | B8: =COUNTIF('Master Hunt List'!A:A,"Yes") -> 0 | E8: Budget | F8: Budget Planner
A9: Application fees marked Yes | B9: =SUMIF('Master Hunt List'!A:A,"Yes",'Master Hunt List'!K:K) -> 0 | E9: Draw odds | F9: Draw Odds
A10: Top recommendation | B10: {=INDEX('Best Bets'!F:F,2)} -> Caprock Canyons SP | E10: History | F10: Hastings Hunt History
E11: Applications | F11: Application Dashboard
A12: How to use
A13: 1. Review Best Bets and Youth Priority.
A14: 2. In Master Hunt List, change Applied from No to Yes as you submit.
A15: 3. Watch Budget Planner update from the Applied column.
A16: 4. After results, add Drawn/Harvest notes in Hunt History.
A17: New Application Workflow
A18: 1. Work from Application Dashboard or Best Bets.
A19: 2. After submitting on TPWD, update Master Hunt List: Applied, Applicant(s), Date Applied, Confirmation #.
A20: 3. When results post, update Draw Status in Master Hunt List.
A21: 4. After a hunt, fill Harvest/Outcome and Post-Hunt Notes.
A23: New sheet added | B23: Application Dashboard
A24: New master fields | B24: Applicant(s), Date Applied, Confirmation #, Draw Status, Result Date, Harvest/Outcome, Post-Hunt Notes

Sheet Best Bets
A1: Rank | B1: Apply? | C1: Hastings Score | D1: Priority | E1: Species Group | F1: Hunt Area | G1: Region | H1: Hunt Category | I1: Adult | J1: Youth | K1: Deadline | L1: Approx Miles | M1: Draw Odds | N1: Recommendation | O1: Source URL
A2: 1 | B2: No | C2: 3.9 | D2: A | E2: Mule Deer | F2: Caprock Canyons SP | G2: Panhandle / Rolling Plains | H2: Youth Gun Deer - Either Sex | I2: No | J2: Yes | K2: 2026-09-01 | L2: 130 | N2: Youth priority — apply | O2: https://tpwd.texas.gov/huntwild/hunt/public/public_hunt_drawing/hunt-category-details.phtml?OCat=YDE
A3: 2 | B3: No | C3: 3.9 | D3: A | E3: Whitetail Deer | F3: Lake McClellan Recreation Area | G3: Panhandle / Rolling Plains | H3: Youth Gun Deer - Antlerless/Spike | I3: No | J3: Yes | K3: 2026-09-15 | L3: 130 | N3: Youth priority — apply | O3: https://tpwd.texas.gov/huntwild/hunt/public/public_hunt_drawing/hunt-category-details.phtml?OCat=YDA
A4: 3 | B4: No | C4: 3.7 | D4: A | E4: Whitetail Deer | F4: Potter County - Cross Bar Mgt. Area | G4: Panhandle / Rolling Plains | H4: Archery Deer | I4: Yes | J4: Yes | K4: 2026-08-15 | L4: 130 | N4: Apply every year | O4: https://tpwd.texas.gov/huntwild/hunt/public/public_hunt_drawing/hunt-category-details.phtml?OCat=ADE
A5: 4 | B5: No | C5: 3.2 | D5: A | E5: Whitetail Deer | F5: Gene Howe WMA | G5: Panhandle / Rolling Plains | H5: Youth Gun Deer - Either Sex | I5: No | J5: Yes | K5: 2026-09-01 | L5: 130 | N5: Youth priority — apply | O5: https://tpwd.texas.gov/huntwild/hunt/public/public_hunt_drawing/hunt-category-details.phtml?OCat=YDE
A6: 5 | B6: No | C6: 3.2 | D6: A | E6: Whitetail Deer | F6: Lake McClellan Recreation Area | G6: Panhandle / Rolling Plains | H6: Youth Gun Deer - Either Sex | I6: No | J6: Yes | K6: 2026-09-01 | L6: 130 | N6: Youth priority — apply | O6: https://tpwd.texas.gov/huntwild/hunt/public/public_hunt_drawing/hunt-category-details.phtml?OCat=YDE
A7: 6 | B7: No | C7: 3.2 | D7: A | E7: Whitetail Deer | F7: Taylor Lakes, Playa Lakes WMA | G7: Panhandle / Rolling Plains | H7: Youth Gun Deer - Either Sex | I7: No | J7: Yes | K7: 2026-09-01 | L7: 130 | N7: Youth priority — apply | O7: https://tpwd.texas.gov/huntwild/hunt/public/public_hunt_drawing/hunt-category-details.phtml?OCat=YDE
A8: 7 | B8: No | C8: 3.2 | D8: A | E8: Whitetail Deer | F8: Gene Howe WMA | G8: Panhandle / Rolling Plains | H8: Youth Gun Deer - Antlerless/Spike | I8: No | J8: Yes | K8: 2026-09-15 | L8: 130 | N8: Youth priority — apply | O8: https://tpwd.texas.gov/huntwild/hunt/public/public_hunt_drawing/hunt-category-details.phtml?OCat=YDA
A9: 8 | B9: No | C9: 3.2 | D9: A | E9: Whitetail Deer | F9: Palo Duro Canyon SP | G9: Panhandle / Rolling Plains | H9: Youth Gun Deer - Antlerless/Spike | I9: No | J9: Yes | K9: 2026-09-15 | L9: 130 | N9: Youth priority — apply | O9: https://tpwd.texas.gov/huntwild/hunt/public/public_hunt_drawing/hunt-category-details.phtml?OCat=YDA
A10: 9 | B10: No | C10: 3.2 | D10: A | E10: Whitetail Deer | F10: Palo Duro Canyon SP | G10: Panhandle / Rolling Plains | H10: Youth Gun Deer - Management | I10: No | J10: Yes | K10: 2026-09-15 | L10: 130 | N10: Youth priority — apply | O10: https://tpwd.texas.gov/huntwild/hunt/public/public_hunt_drawing/hunt-category-details.phtml?OCat=YDM
A11: 10 | B11: No | C11: 3.2 | D11: A | E11: Mule Deer | F11: Yoakum Dunes WMA | G11: Panhandle / Rolling Plains | H11: Youth Gun Deer - Management | I11: No | J11: Yes | K11: 2026-09-15 | L11: 130 | N11: Youth priority — apply | O11: https://tpwd.texas.gov/huntwild/hunt/public/public_hunt_drawing/hunt-category-details.phtml?OCat=YDM
A12: 11 | B12: No | C12: 3.2 | D12: A | E12: Whitetail Deer | F12: Buffalo Lake NWR | G12: Panhandle / Rolling Plains | H12: National Refuge Youth Deer | I12: No | J12: Yes | K12: 2026-10-01 | L12: 130 | N12: Youth priority — apply | O12: https://tpwd.texas.gov/huntwild/hunt/public/public_hunt_drawing/hunt-category-details.phtml?OCat=NYD
A13: 12 | B13: No | C13: 2.9 | D13: A | E13: Whitetail Deer | F13: Gene Howe WMA | G13: Panhandle / Rolling Plains | H13: Archery Deer | I13: Yes | J13: Yes | K13: 2026-08-15 | L13: 130 | N13: Apply every year | O13: https://tpwd.texas.gov/huntwild/hunt/public/public_hunt_drawing/hunt-category-details.phtml?OCat=ADE
... A61: 60 | B61: No | C61: 2.5 | D61: A | E61: Whitetail Deer | F61: Alazan Bayou WMA | G61: East Texas / Pineywoods | H61: Youth Gun Deer - Either Sex | I61: No | J61: Yes | K61: 2026-09-01 | L61: 570 | N61: Youth priority — apply | O61: https://tpwd.texas.gov/huntwild/hunt/public/public_hunt_drawing/hunt-category-details.phtml?OCat=YDE

Sheet Master Hunt List
A1: Applied | B1: Priority | C1: Species Group | D1: Hunt Area | E1: Region | F1: Hunt Category | G1: Adult | H1: Youth | I1: Application Deadline | J1: Hunt Window | K1: Application Fee | L1: Estimated Permit Fee | M1: Permits/Groups | N1: Applicants Last Year | O1: Draw Odds | P1: Approx Miles from Amarillo | Q1: Drive Zone | R1: Camping Notes | S1: Backpack Rating | T1: Past Drawn by Hastings | U1: Notes | V1: Source URL | W1: Odds Score | X1: Distance Score | Y1: Youth Fit Score | Z1: Camping Score | AA1: Backpack Score | AB1: Past Draw Bonus | AC1: Hastings Score | AD1: Estimated Total If Drawn | AE1: Deadline Month | AF1: Applicant(s) | AG1: Date Applied | AH1: TPWD Confirmation # | AI1: Draw Status | AJ1: Draw Result Date | AK1: Harvest/Outcome | AL1: Post-Hunt Notes | AM1: Official Category Link | AN1: TPWD Area / Brochure Search | AO1: TPWD Apply Portal | AP1: Google Maps | AQ1: Preference Adjustment | AR1: Priority Reason
A2: No | B2: A | C2: Mule Deer | D2: Big Bend Ranch SP | E2: Trans-Pecos / West Texas | F2: Archery Mule Deer | G2: Yes | H2: Yes | I2: 2026-08-15 | J2: See TPWD category page | K2: 3 | P2: 520 | Q2: Statewide | R2: Research before draw; property brochure linked from TPWD | S2: High | T2: No | U2: Verified in TPWD 2026-2027 statewide deer category catalog. West Texas/El Paso-region opportunity; prioritize for mule deer adventure value. V5 preference rule: High priority: public-land archery mule deer fits spot-and-stalk preference. | V2: https://tpwd.texas.gov/huntwild/hunt/public/public_hunt_drawing/hunt-category-details.phtml?OCat=AMD | W2: 2 | X2: 2 | Y2: 4 | Z2: 3 | AA2: 4 | AB2: 0 | AC2: 4.5 | AE2: 2026-08-15 | AM2: https://tpwd.texas.gov/huntwild/hunt/public/public_hunt_drawing/hunt-category-details.phtml?OCat=AMD | AN2: https://tpwd.texas.gov/search/?q=Big+Bend+Ranch+SP+public+hunting+brochure | AO2: https://apps.tpwd.state.tx.us/huntwild/hunt/public/public_hunt_drawing/ | AP2: https://www.google.com/maps/search/?api=1&query=Big+Bend+Ranch+SP%2C+Texas | AQ2: 1 | AR2: High priority: public-land archery mule deer fits spot-and-stalk preference
A3: No | B3: A | C3: Mule Deer | D3: Black Gap WMA | E3: Trans-Pecos / West Texas | F3: Archery Mule Deer | G3: Yes | H3: Yes | I3: 2026-08-15 | J3: See TPWD category page | K3: 3 | P3: 520 | Q3: Statewide | R3: Research before draw; property brochure linked from TPWD | S3: High | T3: No | U3: Verified in TPWD 2026-2027 statewide deer category catalog. West Texas/El Paso-region opportunity; prioritize for mule deer adventure value. V5 preference rule: High priority: public-land archery mule deer fits spot-and-stalk preference. | V3: https://tpwd.texas.gov/huntwild/hunt/public/public_hunt_drawing/hunt-category-details.phtml?OCat=AMD | W3: 2 | X3: 2 | Y3: 4 | Z3: 3 | AA3: 4 | AB3: 0 | AC3: 4.5 | AE3: 2026-08-15 | AM3: https://tpwd.texas.gov/huntwild/hunt/public/public_hunt_drawing/hunt-category-details.phtml?OCat=AMD | AN3: https://tpwd.texas.gov/search/?q=Black+Gap+WMA+public+hunting+brochure | AO3: https://apps.tpwd.state.tx.us/huntwild/hunt/public/public_hunt_drawing/ | AP3: https://www.google.com/maps/search/?api=1&query=Black+Gap+WMA%2C+Texas | AQ3: 1 | AR3: High priority: public-land archery mule deer fits spot-and-stalk preference
A4: No | B4: A | C4: Mule Deer | D4: Elephant Mountain WMA | E4: Trans-Pecos / West Texas | F4: Archery Mule Deer | G4: Yes | H4: Yes | I4: 2026-08-15 | J4: See TPWD category page | K4: 3 | P4: 520 | Q4: Statewide | R4: Research before draw; property brochure linked from TPWD | S4: High | T4: No | U4: Verified in TPWD 2026-2027 statewide deer category catalog. West Texas/El Paso-region opportunity; prioritize for mule deer adventure value. V5 preference rule: High priority: public-land archery mule deer fits spot-and-stalk preference. | V4: https://tpwd.texas.gov/huntwild/hunt/public/public_hunt_drawing/hunt-category-details.phtml?OCat=AMD | W4: 2 | X4: 2 | Y4: 4 | Z4: 3 | AA4: 4 | AB4: 0 | AC4: 4.5 | AE4: 2026-08-15 | AM4: https://tpwd.texas.gov/huntwild/hunt/public/public_hunt_drawing/hunt-category-details.phtml?OCat=AMD | AN4: https://tpwd.texas.gov/search/?q=Elephant+Mountain+WMA+public+hunting+brochure | AO4: https://apps.tpwd.state.tx.us/huntwild/hunt/public/public_hunt_drawing/ | AP4: https://www.google.com/maps/search/?api=1&query=Elephant+Mountain+WMA%2C+Texas | AQ4: 1 | AR4: High priority: public-land archery mule deer fits spot-and-stalk preference
A5: No | B5: A | C5: Mule Deer | D5: Matador WMA | E5: Panhandle / Rolling Plains | F5: Archery Mule Deer | G5: Yes | H5: Yes | I5: 2026-08-15 | J5: See TPWD category page | K5: 3 | P5: 130 | Q5: Core | R5: Research before draw; property brochure linked from TPWD | S5: High | T5: No | U5: Verified in TPWD 2026-2027 statewide deer category catalog. V5 preference rule: High priority: public-land archery mule deer fits spot-and-stalk preference. | V5: https://tpwd.texas.gov/huntwild/hunt/public/public_hunt_drawing/hunt-category-details.phtml?OCat=AMD | W5: 2 | X5: 5 | Y5: 4 | Z5: 3 | AA5: 4 | AB5: 0 | AC5: 4.5 | AE5: 2026-08-15 | AM5: https://tpwd.texas.gov/huntwild/hunt/public/public_hunt_drawing/hunt-category-details.phtml?OCat=AMD | AN5: https://tpwd.texas.gov/search/?q=Matador+WMA+public+hunting+brochure | AO5: https://apps.tpwd.state.tx.us/huntwild/hunt/public/public_hunt_drawing/ | AP5: https://www.google.com/maps/search/?api=1&query=Matador+WMA%2C+Texas | AQ5: 1 | AR5: High priority: public-land archery mule deer fits spot-and-stalk preference
A6: No | B6: A | C6: Mule Deer | D6: Potter County - Cross Bar Mgt. Area | E6: Panhandle / Rolling Plains | F6: Archery Mule Deer | G6: Yes | H6: Yes | I6: 2026-08-15 | J6: See TPWD category page | K6: 3 | P6: 130 | Q6: Core | R6: Research before draw; property brochure linked from TPWD | S6: High | T6: No | U6: Verified in TPWD 2026-2027 statewide deer category catalog. V5 preference rule: High priority: public-land archery mule deer fits spot-and-stalk preference. | V6: https://tpwd.texas.gov/huntwild/hunt/public/public_hunt_drawing/hunt-category-details.phtml?OCat=AMD | W6: 2 | X6: 5 | Y6: 4 | Z6: 3 | AA6: 4 | AB6: 0 | AC6: 4.5 | AE6: 2026-08-15 | AM6: https://tpwd.texas.gov/huntwild/hunt/public/public_hunt_drawing/hunt-category-details.phtml?OCat=AMD | AN6: https://tpwd.texas.gov/search/?q=Potter+County+-+Cross+Bar+Mgt.+Area+public+hunting+brochure | AO6: https://apps.tpwd.state.tx.us/huntwild/hunt/public/public_hunt_drawing/ | AP6: https://www.google.com/maps/search/?api=1&query=Potter+County+-+Cross+Bar+Mgt.+Area%2C+Texas | AQ6: 1 | AR6: High priority: public-land archery mule deer fits spot-and-stalk preference
A7: No | B7: B | C7: Whitetail Deer | D7: Abilene SP | E7: West-Central Texas | F7: Archery Deer | G7: Yes | H7: Yes | I7: 2026-08-15 | J7: See TPWD category page | K7: 3 | P7: 300 | Q7: Extended | R7: Research before draw; property brochure linked from TPWD | S7: Low | T7: No | U7: Verified in TPWD 2026-2027 statewide deer category catalog. V5 preference rule: Lower priority: archery whitetail is more than 200 miles from Amarillo. | V7: https://tpwd.texas.gov/huntwild/hunt/public/public_hunt_drawing/hunt-category-details.phtml?OCat=ADE | W7: 2 | X7: 4 | Y7: 4 | Z7: 3 | AA7: 2 | AB7: 0 | AC7: 1.6 | AE7: 2026-08-15 | AM7: https://tpwd.texas.gov/huntwild/hunt/public/public_hunt_drawing/hunt-category-details.phtml?OCat=ADE | AN7: https://tpwd.texas.gov/search/?q=Abilene+SP+public+hunting+brochure | AO7: https://apps.tpwd.state.tx.us/huntwild/hunt/public/public_hunt_drawing/ | AP7: https://www.google.com/maps/search/?api=1&query=Abilene+SP%2C+Texas | AQ7: -1 | AR7: Lower priority: archery whitetail is more than 200 miles from Amarillo
A8: No | B8: B | C8: Whitetail Deer | D8: Chaparral WMA | E8: South Texas / Rio Grande Valley | F8: Archery Deer | G8: Yes | H8: Yes | I8: 2026-08-15 | J8: See TPWD category page | K8: 3 | P8: 700 | Q8: Long Haul | R8: Research before draw; property brochure linked from TPWD | S8: Low | T8: No | U8: Verified in TPWD 2026-2027 statewide deer category catalog. V5 preference rule: Lower priority: archery whitetail is more than 200 miles from Amarillo. | V8: https://tpwd.texas.gov/huntwild/hunt/public/public_hunt_drawing/hunt-category-details.phtml?OCat=ADE | W8: 2 | X8: 1 | Y8: 4 | Z8: 3 | AA8: 2 | AB8: 0 | AC8: 1.1 | AE8: 2026-08-15 | AM8: https://tpwd.texas.gov/huntwild/hunt/public/public_hunt_drawing/hunt-category-details.phtml?OCat=ADE | AN8: https://tpwd.texas.gov/search/?q=Chaparral+WMA+public+hunting+brochure | AO8: https://apps.tpwd.state.tx.us/huntwild/hunt/public/public_hunt_drawing/ | AP8: https://www.google.com/maps/search/?api=1&query=Chaparral+WMA%2C+Texas | AQ8: -1 | AR8: Lower priority: archery whitetail is more than 200 miles from Amarillo
A9: No | B9: B | C9: Whitetail Deer | D9: Choke Canyon SP - North Shore Unit | E9: South Texas / Rio Grande Valley | F9: Archery Deer | G9: Yes | H9: Yes | I9: 2026-08-15 | J9: See TPWD category page | K9: 3 | P9: 700 | Q9: Long Haul | R9: Research before draw; property brochure linked from TPWD | S9: Low | T9: No | U9: Verified in TPWD 2026-2027 statewide deer category catalog. V5 preference rule: Lower priority: archery whitetail is more than 200 miles from Amarillo. | V9: https://tpwd.texas.gov/huntwild/hunt/public/public_hunt_drawing/hunt-category-details.phtml?OCat=ADE | W9: 2 | X9: 1 | Y9: 4 | Z9: 3 | AA9: 2 | AB9: 0 | AC9: 1.1 | AE9: 2026-08-15 | AM9: https://tpwd.texas.gov/huntwild/hunt/public/public_hunt_drawing/hunt-category-details.phtml?OCat=ADE | AN9: https://tpwd.texas.gov/search/?q=Choke+Canyon+SP+-+North+Shore+Unit+public+hunting+brochure | AO9: https://apps.tpwd.state.tx.us/huntwild/hunt/public/public_hunt_drawing/ | AP9: https://www.google.com/maps/search/?api=1&query=Choke+Canyon+SP+-+North+Shore+Unit%2C+Texas | AQ9: -1 | AR9: Lower priority: archery whitetail is more than 200 miles from Amarillo
A10: No | B10: B | C10: Whitetail Deer | D10: Colorado Bend SP | E10: Central Texas / Austin | F10: Archery Deer | G10: Yes | H10: Yes | I10: 2026-08-15 | J10: See TPWD category page | K10: 3 | P10: 490 | Q10: Statewide | R10: Research before draw; property brochure linked from TPWD | S10: Low | T10: No | U10: Verified in TPWD 2026-2027 statewide deer category catalog. V5 preference rule: Lower priority: archery whitetail is more than 200 miles from Amarillo. | V10: https://tpwd.texas.gov/huntwild/hunt/public/public_hunt_drawing/hunt-category-details.phtml?OCat=ADE | W10: 2 | X10: 2 | Y10: 4 | Z10: 3 | AA10: 2 | AB10: 0 | AC10: 1.3 | AE10: 2026-08-15 | AM10: https://tpwd.texas.gov/huntwild/hunt/public/public_hunt_drawing/hunt-category-details.phtml?OCat=ADE | AN10: https://tpwd.texas.gov/search/?q=Colorado+Bend+SP+public+hunting+brochure | AO10: https://apps.tpwd.state.tx.us/huntwild/hunt/public/public_hunt_drawing/ | AP10: https://www.google.com/maps/search/?api=1&query=Colorado+Bend+SP%2C+Texas | AQ10: -1 | AR10: Lower priority: archery whitetail is more than 200 miles from Amarillo
A11: No | B11: B | C11: Whitetail Deer | D11: Copper Breaks SP | E11: West-Central Texas | F11: Archery Deer | G11: Yes | H11: Yes | I11: 2026-08-15 | J11: See TPWD category page | K11: 3 | P11: 300 | Q11: Extended | R11: Research before draw; property brochure linked from TPWD | S11: Low | T11: No | U11: Verified in TPWD 2026-2027 statewide deer category catalog. V5 preference rule: Lower priority: archery whitetail is more than 200 miles from Amarillo. | V11: https://tpwd.texas.gov/huntwild/hunt/public/public_hunt_drawing/hunt-category-details.phtml?OCat=ADE | W11: 2 | X11: 4 | Y11: 4 | Z11: 3 | AA11: 2 | AB11: 0 | AC11: 1.6 | AE11: 2026-08-15 | AM11: https://tpwd.texas.gov/huntwild/hunt/public/public_hunt_drawing/hunt-category-details.phtml?OCat=ADE | AN11: https://tpwd.texas.gov/search/?q=Copper+Breaks+SP+public+hunting+brochure | AO11: https://apps.tpwd.state.tx.us/huntwild/hunt/public/public_hunt_drawing/ | AP11: https://www.google.com/maps/search/?api=1&query=Copper+Breaks+SP%2C+Texas | AQ11: -1 | AR11: Lower priority: archery whitetail is more than 200 miles from Amarillo
A12: No | B12: B | C12: Whitetail Deer | D12: Enchanted Rock SNA | E12: Hill Country / San Antonio | F12: Archery Deer | G12: Yes | H12: Yes | I12: 2026-08-15 | J12: See TPWD category page | K12: 3 | P12: 520 | Q12: Statewide | R12: Research before draw; property brochure linked from TPWD | S12: Low | T12: No | U12: Verified in TPWD 2026-2027 statewide deer category catalog. V5 preference rule: Lower priority: archery whitetail is more than 200 miles from Amarillo. | V12: https://tpwd.texas.gov/huntwild/hunt/public/public_hunt_drawing/hunt-category-details.phtml?OCat=ADE | W12: 2 | X12: 2 | Y12: 4 | Z12: 3 | AA12: 2 | AB12: 0 | AC12: 1.3 | AE12: 2026-08-15 | AM12: https://tpwd.texas.gov/huntwild/hunt/public/public_hunt_drawing/hunt-category-details.phtml?OCat=ADE | AN12: https://tpwd.texas.gov/search/?q=Enchanted+Rock+SNA+public+hunting+brochure | AO12: https://apps.tpwd.state.tx.us/huntwild/hunt/public/public_hunt_drawing/ | AP12: https://www.google.com/maps/search/?api=1&query=Enchanted+Rock+SNA%2C+Texas | AQ12: -1 | AR12: Lower priority: archery whitetail is more than 200 miles from Amarillo
A13: No | B13: B | C13: Whitetail Deer | D13: Fort Boggy SP | E13: North Texas / DFW | F13: Archery Deer | G13: Yes | H13: Yes | I13: 2026-08-15 | J13: See TPWD category page | K13: 3 | P13: 360 | Q13: Extended | R13: Research before draw; property brochure linked from TPWD | S13: Low | T13: No | U13: Verified in TPWD 2026-2027 statewide deer category catalog. V5 preference rule: Lower priority: archery whitetail is more than 200 miles from Amarillo. | V13: https://tpwd.texas.gov/huntwild/hunt/public/public_hunt_drawing/hunt-category-details.phtml?OCat=ADE | W13: 2 | X13: 3 | Y13: 4 | Z13: 3 | AA13: 2 | AB13: 0 | AC13: 1.5 | AE13: 2026-08-15 | AM13: https://tpwd.texas.gov/huntwild/hunt/public/public_hunt_drawing/hunt-category-details.phtml?OCat=ADE | AN13: https://tpwd.texas.gov/search/?q=Fort+Boggy+SP+public+hunting+brochure | AO13: https://apps.tpwd.state.tx.us/huntwild/hunt/public/public_hunt_drawing/ | AP13: https://www.google.com/maps/search/?api=1&query=Fort+Boggy+SP%2C+Texas | AQ13: -1 | AR13: Lower priority: archery whitetail is more than 200 miles from Amarillo
... A29: No | B29: B | C29: Whitetail Deer | D29: Roger Fawcett WMA | E29: West-Central Texas | F29: Archery Deer | G29: Yes | H29: Yes | I29: 2026-08-15 | J29: See TPWD category page | K29: 3 | P29: 300 | Q29: Extended | R29: Research before draw; property brochure linked from TPWD | S29: Low | T29: No | U29: Verified in TPWD 2026-2027 statewide deer category catalog. V5 preference rule: Lower priority: archery whitetail is more than 200 miles from Amarillo. | V29: https://tpwd.texas.gov/huntwild/hunt/public/public_hunt_drawing/hunt-category-details.phtml?OCat=ADE | W29: 2 | X29: 4 | Y29: 4 | Z29: 3 | AA29: 2 | AB29: 0 | AC29: 1.6 | AE29: 2026-08-15 | AM29: https://tpwd.texas.gov/huntwild/hunt/public/public_hunt_drawing/hunt-category-details.phtml?OCat=ADE | AN29: https://tpwd.texas.gov/search/?q=Roger+Fawcett+WMA+public+hunting+brochure | AO29: https://apps.tpwd.state.tx.us/huntwild/hunt/public/public_hunt_drawing/ | AP29: https://www.google.com/maps/search/?api=1&query=Roger+Fawcett+WMA%2C+Texas | AQ29: -1 | AR29: Lower priority: archery whitetail is more than 200 miles from Amarillo
A30: No | B30: A | C30: Mule Deer | D30: Big Bend Ranch SP | E30: Trans-Pecos / West Texas | F30: Youth Gun Deer - Either Sex | G30: No | H30: Yes | I30: 2026-09-01 | J30: See TPWD category page | K30: 0 | L30: 0 | P30: 520 | Q30: Statewide | R30: Research before draw; property brochure linked from TPWD | S30: High | T30: No | U30: Verified in TPWD 2026-2027 statewide deer category catalog. West Texas/El Paso-region opportunity; prioritize for mule deer adventure value. | V30: https://tpwd.texas.gov/huntwild/hunt/public/public_hunt_drawing/hunt-category-details.phtml?OCat=YDE | W30: 2 | X30: 2 | Y30: 5 | Z30: 3 | AA30: 4 | AB30: 0 | AC30: 2.7 | AD30: 0 | AE30: 2026-09-01 | AM30: https://tpwd.texas.gov/huntwild/hunt/public/public_hunt_drawing/hunt-category-details.phtml?OCat=YDE | AN30: https://tpwd.texas.gov/search/?q=Big+Bend+Ranch+SP+public+hunting+brochure | AO30: https://apps.tpwd.state.tx.us/huntwild/hunt/public/public_hunt_drawing/ | AP30: https://www.google.com/maps/search/?api=1&query=Big+Bend+Ranch+SP%2C+Texas | AQ30: 0 | AR30: Standard Hastings ranking
A31: No | B31: A | C31: Mule Deer | D31: Caprock Canyons SP | E31: Panhandle / Rolling Plains | F31: Youth Gun Deer - Either Sex | G31: No | H31: Yes | I31: 2026-09-01 | J31: See TPWD category page | K31: 0 | L31: 0 | P31: 130 | Q31: Core | R31: Research before draw; property brochure linked from TPWD | S31: High | T31: Yes | U31: Verified in TPWD 2026-2027 statewide deer category catalog. | V31: https://tpwd.texas.gov/huntwild/hunt/public/public_hunt_drawing/hunt-category-details.phtml?OCat=YDE | W31: 2 | X31: 5 | Y31: 5 | Z31: 3 | AA31: 4 | AB31: 5 | AC31: 3.9 | AD31: 0 | AE31: 2026-09-01 | AM31: https://tpwd.texas.gov/huntwild/hunt/public/public_hunt_drawing/hunt-category-details.phtml?OCat=YDE | AN31: https://tpwd.texas.gov/search/?q=Caprock+Canyons+SP+public+hunting+brochure | AO31: https://apps.tpwd.state.tx.us/huntwild/hunt/public/public_hunt_drawing/ | AP31: https://www.google.com/maps/search/?api=1&query=Caprock+Canyons+SP%2C+Texas | AQ31: 0 | AR31: Standard Hastings ranking
A32: No | B32: A | C32: Whitetail Deer | D32: Abilene SP | E32: West-Central Texas | F32: Youth Gun Deer - Either Sex | G32: No | H32: Yes | I32: 2026-09-01 | J32: See TPWD category page | K32: 0 | L32: 0 | P32: 300 | Q32: Extended | R32: Research before draw; property brochure linked from TPWD | S32: Low | T32: No | U32: Verified in TPWD 2026-2027 statewide deer category catalog. | V32: https://tpwd.texas.gov/huntwild/hunt/public/public_hunt_drawing/hunt-category-details.phtml?OCat=YDE | W32: 2 | X32: 4 | Y32: 5 | Z32: 3 | AA32: 2 | AB32: 0 | AC32: 2.9 | AD32: 0 | AE32: 2026-09-01 | AM32: https://tpwd.texas.gov/huntwild/hunt/public/public_hunt_drawing/hunt-category-details.phtml?OCat=YDE | AN32: https://tpwd.texas.gov/search/?q=Abilene+SP+public+hunting+brochure | AO32: https://apps.tpwd.state.tx.us/huntwild/hunt/public/public_hunt_drawing/ | AP32: https://www.google.com/maps/search/?api=1&query=Abilene+SP%2C+Texas | AQ32: 0 | AR32: Standard Hastings ranking
A33: No | B33: A | C33: Whitetail Deer | D33: Alazan Bayou WMA | E33: East Texas / Pineywoods | F33: Youth Gun Deer - Either Sex | G33: No | H33: Yes | I33: 2026-09-01 | J33: See TPWD category page | K33: 0 | L33: 0 | P33: 570 | Q33: Statewide | R33: Research before draw; property brochure linked from TPWD | S33: Low | T33: No | U33: Verified in TPWD 2026-2027 statewide deer category catalog. | V33: https://tpwd.texas.gov/huntwild/hunt/public/public_hunt_drawing/hunt-category-details.phtml?OCat=YDE | W33: 2 | X33: 2 | Y33: 5 | Z33: 3 | AA33: 2 | AB33: 0 | AC33: 2.5 | AD33: 0 | AE33: 2026-09-01 | AM33: https://tpwd.texas.gov/huntwild/hunt/public/public_hunt_drawing/hunt-category-details.phtml?OCat=YDE | AN33: https://tpwd.texas.gov/search/?q=Alazan+Bayou+WMA+public+hunting+brochure | AO33: https://apps.tpwd.state.tx.us/huntwild/hunt/public/public_hunt_drawing/ | AP33: https://www.google.com/maps/search/?api=1&query=Alazan+Bayou+WMA%2C+Texas | AQ33: 0 | AR33: Standard Hastings ranking
A34: No | B34: A | C34: Whitetail Deer | D34: Atlanta SP | E34: East Texas / Pineywoods | F34: Youth Gun Deer - Either Sex | G34: No | H34: Yes | I34: 2026-09-01 | J34: See TPWD category page | K34: 0 | L34: 0 | P34: 570 | Q34: Statewide | R34: Research before draw; property brochure linked from TPWD | S34: Low | T34: No | U34: Verified in TPWD 2026-2027 statewide deer category catalog. | V34: https://tpwd.texas.gov/huntwild/hunt/public/public_hunt_drawing/hunt-category-details.phtml?OCat=YDE | W34: 2 | X34: 2 | Y34: 5 | Z34: 3 | AA34: 2 | AB34: 0 | AC34: 2.5 | AD34: 0 | AE34: 2026-09-01 | AM34: https://tpwd.texas.gov/huntwild/hunt/public/public_hunt_drawing/hunt-category-details.phtml?OCat=YDE | AN34: https://tpwd.texas.gov/search/?q=Atlanta+SP+public+hunting+brochure | AO34: https://apps.tpwd.state.tx.us/huntwild/hunt/public/public_hunt_drawing/ | AP34: https://www.google.com/maps/search/?api=1&query=Atlanta+SP%2C+Texas | AQ34: 0 | AR34: Standard Hastings ranking
A35: No | B35: A | C35: Whitetail Deer | D35: Bastrop SP | E35: Central Texas / Austin | F35: Youth Gun Deer - Either Sex | G35: No | H35: Yes | I35: 2026-09-01 | J35: See TPWD category page | K35: 0 | L35: 0 | P35: 490 | Q35: Statewide | R35: Research before draw; property brochure linked from TPWD | S35: Low | T35: No | U35: Verified in TPWD 2026-2027 statewide deer category catalog. | V35: https://tpwd.texas.gov/huntwild/hunt/public/public_hunt_drawing/hunt-category-details.phtml?OCat=YDE | W35: 2 | X35: 2 | Y35: 5 | Z35: 3 | AA35: 2 | AB35: 0 | AC35: 2.5 | AD35: 0 | AE35: 2026-09-01 | AM35: https://tpwd.texas.gov/huntwild/hunt/public/public_hunt_drawing/hunt-category-details.phtml?OCat=YDE | AN35: https://tpwd.texas.gov/search/?q=Bastrop+SP+public+hunting+brochure | AO35: https://apps.tpwd.state.tx.us/huntwild/hunt/public/public_hunt_drawing/ | AP35: https://www.google.com/maps/search/?api=1&query=Bastrop+SP%2C+Texas | AQ35: 0 | AR35: Standard Hastings ranking
A36: No | B36: A | C36: Whitetail Deer | D36: Chaparral WMA | E36: South Texas / Rio Grande Valley | F36: Youth Gun Deer - Either Sex | G36: No | H36: Yes | I36: 2026-09-01 | J36: See TPWD category page | K36: 0 | L36: 0 | P36: 700 | Q36: Long Haul | R36: Research before draw; property brochure linked from TPWD | S36: Low | T36: No | U36: Verified in TPWD 2026-2027 statewide deer category catalog. | V36: https://tpwd.texas.gov/huntwild/hunt/public/public_hunt_drawing/hunt-category-details.phtml?OCat=YDE | W36: 2 | X36: 1 | Y36: 5 | Z36: 3 | AA36: 2 | AB36: 0 | AC36: 2.4 | AD36: 0 | AE36: 2026-09-01 | AM36: https://tpwd.texas.gov/huntwild/hunt/public/public_hunt_drawing/hunt-category-details.phtml?OCat=YDE | AN36: https://tpwd.texas.gov/search/?q=Chaparral+WMA+public+hunting+brochure | AO36: https://apps.tpwd.state.tx.us/huntwild/hunt/public/public_hunt_drawing/ | AP36: https://www.google.com/maps/search/?api=1&query=Chaparral+WMA%2C+Texas | AQ36: 0 | AR36: Standard Hastings ranking
A37: No | B37: A | C37: Whitetail Deer | D37: Choke Canyon SP - North Shore Unit | E37: South Texas / Rio Grande Valley | F37: Youth Gun Deer - Either Sex | G37: No | H37: Yes | I37: 2026-09-01 | J37: See TPWD category page | K37: 0 | L37: 0 | P37: 700 | Q37: Long Haul | R37: Research before draw; property brochure linked from TPWD | S37: Low | T37: No | U37: Verified in TPWD 2026-2027 statewide deer category catalog. | V37: https://tpwd.texas.gov/huntwild/hunt/public/public_hunt_drawing/hunt-category-details.phtml?OCat=YDE | W37: 2 | X37: 1 | Y37: 5 | Z37: 3 | AA37: 2 | AB37: 0 | AC37: 2.4 | AD37: 0 | AE37: 2026-09-01 | AM37: https://tpwd.texas.gov/huntwild/hunt/public/public_hunt_drawing/hunt-category-details.phtml?OCat=YDE | AN37: https://tpwd.texas.gov/search/?q=Choke+Canyon+SP+-+North+Shore+Unit+public+hunting+brochure | AO37: https://apps.tpwd.state.tx.us/huntwild/hunt/public/public_hunt_drawing/ | AP37: https://www.google.com/maps/search/?api=1&query=Choke+Canyon+SP+-+North+Shore+Unit%2C+Texas | AQ37: 0 | AR37: Standard Hastings ranking
A38: No | B38: A | C38: Whitetail Deer | D38: Colorado Bend SP | E38: Central Texas / Austin | F38: Youth Gun Deer - Either Sex | G38: No | H38: Yes | I38: 2026-09-01 | J38: See TPWD category page | K38: 0 | L38: 0 | P38: 490 | Q38: Statewide | R38: Research before draw; property brochure linked from TPWD | S38: Low | T38: No | U38: Verified in TPWD 2026-2027 statewide deer category catalog. | V38: https://tpwd.texas.gov/huntwild/hunt/public/public_hunt_drawing/hunt-category-details.phtml?OCat=YDE | W38: 2 | X38: 2 | Y38: 5 | Z38: 3 | AA38: 2 | AB38: 0 | AC38: 2.5 | AD38: 0 | AE38: 2026-09-01 | AM38: https://tpwd.texas.gov/huntwild/hunt/public/public_hunt_drawing/hunt-category-details.phtml?OCat=YDE | AN38: https://tpwd.texas.gov/search/?q=Colorado+Bend+SP+public+hunting+brochure | AO38: https://apps.tpwd.state.tx.us/huntwild/hunt/public/public_hunt_drawing/ | AP38: https://www.google.com/maps/search/?api=1&query=Colorado+Bend+SP%2C+Texas | AQ38: 0 | AR38: Standard Hastings ranking
A39: No | B39: A | C39: Whitetail Deer | D39: Cooper WMA | E39: North Texas / DFW | F39: Youth Gun Deer - Either Sex | G39: No | H39: Yes | I39: 2026-09-01 | J39: See TPWD category page | K39: 0 | L39: 0 | P39: 360 | Q39: Extended | R39: Research before draw; property brochure linked from TPWD | S39: Low | T39: No | U39: Verified in TPWD 2026-2027 statewide deer category catalog. | V39: https://tpwd.texas.gov/huntwild/hunt/public/public_hunt_drawing/hunt-category-details.phtml?OCat=YDE | W39: 2 | X39: 3 | Y39: 5 | Z39: 3 | AA39: 2 | AB39: 0 | AC39: 2.7 | AD39: 0 | AE39: 2026-09-01 | AM39: https://tpwd.texas.gov/huntwild/hunt/public/public_hunt_drawing/hunt-category-details.phtml?OCat=YDE | AN39: https://tpwd.texas.gov/search/?q=Cooper+WMA+public+hunting+brochure | AO39: https://apps.tpwd.state.tx.us/huntwild/hunt/public/public_hunt_drawing/ | AP39: https://www.google.com/maps/search/?api=1&query=Cooper+WMA%2C+Texas | AQ39: 0 | AR39: Standard Hastings ranking
A40: No | B40: A | C40: Whitetail Deer | D40: Devil's Sinkhole SNA | E40: Hill Country / San Antonio | F40: Youth Gun Deer - Either Sex | G40: No | H40: Yes | I40: 2026-09-01 | J40: See TPWD category page | K40: 0 | L40: 0 | P40: 520 | Q40: Statewide | R40: Research before draw; property brochure linked from TPWD | S40: Low | T40: No | U40: Verified in TPWD 2026-2027 statewide deer category catalog. | V40: https://tpwd.texas.gov/huntwild/hunt/public/public_hunt_drawing/hunt-category-details.phtml?OCat=YDE | W40: 2 | X40: 2 | Y40: 5 | Z40: 3 | AA40: 2 | AB40: 0 | AC40: 2.5 | AD40: 0 | AE40: 2026-09-01 | AM40: https://tpwd.texas.gov/huntwild/hunt/public/public_hunt_drawing/hunt-category-details.phtml?OCat=YDE | AN40: https://tpwd.texas.gov/search/?q=Devil%27s+Sinkhole+SNA+public+hunting+brochure | AO40: https://apps.tpwd.state.tx.us/huntwild/hunt/public/public_hunt_drawing/ | AP40: https://www.google.com/maps/search/?api=1&query=Devil%27s+Sinkhole+SNA%2C+Texas | AQ40: 0 | AR40: Standard Hastings ranking
A41: No | B41: A | C41: Whitetail Deer | D41: Devils River SNA - Dan Allen Hughes | E41: Trans-Pecos / West Texas | F41: Youth Gun Deer - Either Sex | G41: No | H41: Yes | I41: 2026-09-01 | J41: See TPWD category page | K41: 0 | L41: 0 | P41: 520 | Q41: Statewide | R41: Research before draw; property brochure linked from TPWD | S41: High | T41: No | U41: Verified in TPWD 2026-2027 statewide deer category catalog. West Texas/El Paso-region opportunity; prioritize for mule deer adventure value. | V41: https://tpwd.texas.gov/huntwild/hunt/public/public_hunt_drawing/hunt-category-details.phtml?OCat=YDE | W41: 2 | X41: 2 | Y41: 5 | Z41: 3 | AA41: 4 | AB41: 0 | AC41: 2.7 | AD41: 0 | AE41: 2026-09-01 | AM41: https://tpwd.texas.gov/huntwild/hunt/public/public_hunt_drawing/hunt-category-details.phtml?OCat=YDE | AN41: https://tpwd.texas.gov/search/?q=Devils+River+SNA+-+Dan+Allen+Hughes+public+hunting+brochure | AO41: https://apps.tpwd.state.tx.us/huntwild/hunt/public/public_hunt_drawing/ | AP41: https://www.google.com/maps/search/?api=1&query=Devils+River+SNA+-+Dan+Allen+Hughes%2C+Texas | AQ41: 0 | AR41: Standard Hastings ranking
... A79: No | B79: A | C79: Whitetail Deer | D79: White Oak Creek WMA | E79: East Texas / Pineywoods | F79: Youth Gun Deer - Either Sex | G79: No | H79: Yes | I79: 2026-09-01 | J79: See TPWD category page | K79: 0 | L79: 0 | P79: 570 | Q79: Statewide | R79: Research before draw; property brochure linked from TPWD | S79: Low | T79: No | U79: Verified in TPWD 2026-2027 statewide deer category catalog. | V79: https://tpwd.texas.gov/huntwild/hunt/public/public_hunt_drawing/hunt-category-details.phtml?OCat=YDE | W79: 2 | X79: 2 | Y79: 5 | Z79: 3 | AA79: 2 | AB79: 0 | AC79: 2.5 | AD79: 0 | AE79: 2026-09-01 | AM79: https://tpwd.texas.gov/huntwild/hunt/public/public_hunt_drawing/hunt-category-details.phtml?OCat=YDE | AN79: https://tpwd.texas.gov/search/?q=White+Oak+Creek+WMA+public+hunting+brochure | AO79: https://apps.tpwd.state.tx.us/huntwild/hunt/public/public_hunt_drawing/ | AP79: https://www.google.com/maps/search/?api=1&query=White+Oak+Creek+WMA%2C+Texas | AQ79: 0 | AR79: Standard Hastings ranking
A80: No | B80: B | C80: Whitetail Deer | D80: Aransas NWR | E80: Houston / Gulf Coast | F80: National Refuge Archery Deer | G80: Yes | H80: Yes | I80: 2026-09-01 | J80: See TPWD category page | K80: 3 | P80: 610 | Q80: Long Haul | R80: Research before draw; property brochure linked from TPWD | S80: Low | T80: No | U80: Verified in TPWD 2026-2027 statewide deer category catalog. Refuge-specific rules and permit fees may apply. V5 preference rule: Lower priority: archery whitetail is more than 200 miles from Amarillo. | V80: https://tpwd.texas.gov/huntwild/hunt/public/public_hunt_drawing/hunt-category-details.phtml?OCat=NAD | W80: 2 | X80: 1 | Y80: 4 | Z80: 3 | AA80: 2 | AB80: 0 | AC80: 1.1 | AE80: 2026-09-01 | AM80: https://tpwd.texas.gov/huntwild/hunt/public/public_hunt_drawing/hunt-category-details.phtml?OCat=NAD | AN80: https://tpwd.texas.gov/search/?q=Aransas+NWR+public+hunting+brochure | AO80: https://apps.tpwd.state.tx.us/huntwild/hunt/public/public_hunt_drawing/ | AP80: https://www.google.com/maps/search/?api=1&query=Aransas+NWR%2C+Texas | AQ80: -1 | AR80: Lower priority: archery whitetail is more than 200 miles from Amarillo
A81: No | B81: B | C81: Whitetail Deer | D81: Balcones Canyonlands NWR | E81: Statewide / Other | F81: E-Postcard Archery Deer | G81: Yes | H81: Yes | I81: 2026-09-01 | J81: See TPWD category page | K81: 0 | L81: 0 | P81: 500 | Q81: Statewide | R81: Research before draw; property brochure linked from TPWD | S81: Low | T81: No | U81: Verified in TPWD 2026-2027 statewide deer category catalog. APH/eligibility rules apply; confirm account and permit requirements. V5 preference rule: Lower priority: archery whitetail is more than 200 miles from Amarillo. | V81: https://tpwd.texas.gov/huntwild/hunt/public/public_hunt_drawing/hunt-category-details.phtml?OCat=EAD | W81: 2 | X81: 2 | Y81: 4 | Z81: 3 | AA81: 2 | AB81: 0 | AC81: 1.3 | AD81: 0 | AE81: 2026-09-01 | AM81: https://tpwd.texas.gov/huntwild/hunt/public/public_hunt_drawing/hunt-category-details.phtml?OCat=EAD | AN81: https://tpwd.texas.gov/search/?q=Balcones+Canyonlands+NWR+public+hunting+brochure | AO81: https://apps.tpwd.state.tx.us/huntwild/hunt/public/public_hunt_drawing/ | AP81: https://www.google.com/maps/search/?api=1&query=Balcones+Canyonlands+NWR%2C+Texas | AQ81: -1 | AR81: Lower priority: archery whitetail is more than 200 miles from Amarillo
A82: No | B82: A | C82: Whitetail Deer | D82: Bandera County - The Nature Conservancy | E82: Hill Country / San Antonio | F82: Private Lands - Antlerless/Spike | G82: Yes | H82: Yes | I82: 2026-09-01 | J82: See TPWD category page | K82: 10 | P82: 520 | Q82: Statewide | R82: Research before draw; property brochure linked from TPWD | S82: Low | T82: No | U82: Verified in TPWD 2026-2027 statewide deer category catalog. | V82: https://tpwd.texas.gov/huntwild/hunt/public/public_hunt_drawing/hunt-category-details.phtml?OCat=PLA | W82: 2 | X82: 2 | Y82: 4 | Z82: 3 | AA82: 2 | AB82: 0 | AC82: 2.3 | AE82: 2026-09-01 | AM82: https://tpwd.texas.gov/huntwild/hunt/public/public_hunt_drawing/hunt-category-details.phtml?OCat=PLA | AN82: https://tpwd.texas.gov/search/?q=Bandera+County+-+The+Nature+Conservancy+public+hunting+brochure | AO82: https://apps.tpwd.state.tx.us/huntwild/hunt/public/public_hunt_drawing/ | AP82: https://www.google.com/maps/search/?api=1&query=Bandera+County+-+The+Nature+Conservancy%2C+Texas | AQ82: 0 | AR82: Standard Hastings ranking
A83: No | B83: A | C83: Whitetail Deer | D83: Bandera County - The Nature Conservancy | E83: Hill Country / San Antonio | F83: Private Lands - Either Sex | G83: Yes | H83: Yes | I83: 2026-09-01 | J83: See TPWD category page | K83: 10 | P83: 520 | Q83: Statewide | R83: Research before draw; property brochure linked from TPWD | S83: Low | T83: No | U83: Verified in TPWD 2026-2027 statewide deer category catalog. | V83: https://tpwd.texas.gov/huntwild/hunt/public/public_hunt_drawing/hunt-category-details.phtml?OCat=PLE | W83: 2 | X83: 2 | Y83: 4 | Z83: 3 | AA83: 2 | AB83: 0 | AC83: 2.3 | AE83: 2026-09-01 | AM83: https://tpwd.texas.gov/huntwild/hunt/public/public_hunt_drawing/hunt-category-details.phtml?OCat=PLE | AN83: https://tpwd.texas.gov/search/?q=Bandera+County+-+The+Nature+Conservancy+public+hunting+brochure | AO83: https://apps.tpwd.state.tx.us/huntwild/hunt/public/public_hunt_drawing/ | AP83: https://www.google.com/maps/search/?api=1&query=Bandera+County+-+The+Nature+Conservancy%2C+Texas | AQ83: 0 | AR83: Standard Hastings ranking
A84: No | B84: B | C84: Whitetail Deer | D84: Big Lake Bottom WMA | E84: Statewide / Other | F84: E-Postcard Archery Deer | G84: Yes | H84: Yes | I84: 2026-09-01 | J84: See TPWD category page | K84: 0 | L84: 0 | P84: 500 | Q84: Statewide | R84: Research before draw; property brochure linked from TPWD | S84: Low | T84: No | U84: Verified in TPWD 2026-2027 statewide deer category catalog. APH/eligibility rules apply; confirm account and permit requirements. V5 preference rule: Lower priority: archery whitetail is more than 200 miles from Amarillo. | V84: https://tpwd.texas.gov/huntwild/hunt/public/public_hunt_drawing/hunt-category-details.phtml?OCat=EAD | W84: 2 | X84: 2 | Y84: 4 | Z84: 3 | AA84: 2 | AB84: 0 | AC84: 1.3 | AD84: 0 | AE84: 2026-09-01 | AM84: https://tpwd.texas.gov/huntwild/hunt/public/public_hunt_drawing/hunt-category-details.phtml?OCat=EAD | AN84: https://tpwd.texas.gov/search/?q=Big+Lake+Bottom+WMA+public+hunting+brochure | AO84: https://apps.tpwd.state.tx.us/huntwild/hunt/public/public_hunt_drawing/ | AP84: https://www.google.com/maps/search/?api=1&query=Big+Lake+Bottom+WMA%2C+Texas | AQ84: -1 | AR84: Lower priority: archery whitetail is more than 200 miles from Amarillo
A85: No | B85: A | C85: Whitetail Deer | D85: Buffalo Lake NWR | E85: Panhandle / Rolling Plains | F85: National Refuge Archery Deer | G85: Yes | H85: Yes | I85: 2026-09-01 | J85: See TPWD category page | K85: 3 | P85: 130 | Q85: Core | R85: Research before draw; property brochure linked from TPWD | S85: High | T85: No | U85: Verified in TPWD 2026-2027 statewide deer category catalog. Refuge-specific rules and permit fees may apply. | V85: https://tpwd.texas.gov/huntwild/hunt/public/public_hunt_drawing/hunt-category-details.phtml?OCat=NAD | W85: 2 | X85: 5 | Y85: 4 | Z85: 3 | AA85: 4 | AB85: 0 | AC85: 2.9 | AE85: 2026-09-01 | AM85: https://tpwd.texas.gov/huntwild/hunt/public/public_hunt_drawing/hunt-category-details.phtml?OCat=NAD | AN85: https://tpwd.texas.gov/search/?q=Buffalo+Lake+NWR+public+hunting+brochure | AO85: https://apps.tpwd.state.tx.us/huntwild/hunt/public/public_hunt_drawing/ | AP85: https://www.google.com/maps/search/?api=1&query=Buffalo+Lake+NWR%2C+Texas | AQ85: 0 | AR85: Standard Hastings ranking
A86: No | B86: A | C86: Whitetail Deer | D86: Comal County Ranch - The Nature Conservancy | E86: Hill Country / San Antonio | F86: Private Lands - Antlerless/Spike | G86: Yes | H86: Yes | I86: 2026-09-01 | J86: See TPWD category page | K86: 10 | P86: 520 | Q86: Statewide | R86: Research before draw; property brochure linked from TPWD | S86: Low | T86: No | U86: Verified in TPWD 2026-2027 statewide deer category catalog. | V86: https://tpwd.texas.gov/huntwild/hunt/public/public_hunt_drawing/hunt-category-details.phtml?OCat=PLA | W86: 2 | X86: 2 | Y86: 4 | Z86: 3 | AA86: 2 | AB86: 0 | AC86: 2.3 | AE86: 2026-09-01 | AM86: https://tpwd.texas.gov/huntwild/hunt/public/public_hunt_drawing/hunt-category-details.phtml?OCat=PLA | AN86: https://tpwd.texas.gov/search/?q=Comal+County+Ranch+-+The+Nature+Conservancy+public+hunting+brochure | AO86: https://apps.tpwd.state.tx.us/huntwild/hunt/public/public_hunt_drawing/ | AP86: https://www.google.com/maps/search/?api=1&query=Comal+County+Ranch+-+The+Nature+Conservancy%2C+Texas | AQ86: 0 | AR86: Standard Hastings ranking
A87: No | B87: A | C87: Whitetail Deer | D87: Comal County Ranch - The Nature Conservancy | E87: Hill Country / San Antonio | F87: Private Lands - Either Sex | G87: Yes | H87: Yes | I87: 2026-09-01 | J87: See TPWD category page | K87: 10 | P87: 520 | Q87: Statewide | R87: Research before draw; property brochure linked from TPWD | S87: Low | T87: No | U87: Verified in TPWD 2026-2027 statewide deer category catalog. | V87: https://tpwd.texas.gov/huntwild/hunt/public/public_hunt_drawing/hunt-category-details.phtml?OCat=PLE | W87: 2 | X87: 2 | Y87: 4 | Z87: 3 | AA87: 2 | AB87: 0 | AC87: 2.3 | AE87: 2026-09-01 | AM87: https://tpwd.texas.gov/huntwild/hunt/public/public_hunt_drawing/hunt-category-details.phtml?OCat=PLE | AN87: https://tpwd.texas.gov/search/?q=Comal+County+Ranch+-+The+Nature+Conservancy+public+hunting+brochure | AO87: https://apps.tpwd.state.tx.us/huntwild/hunt/public/public_hunt_drawing/ | AP87: https://www.google.com/maps/search/?api=1&query=Comal+County+Ranch+-+The+Nature+Conservancy%2C+Texas | AQ87: 0 | AR87: Standard Hastings ranking
A88: No | B88: A | C88: Whitetail Deer | D88: DeWitt County Ranch | E88: Houston / Gulf Coast | F88: Private Lands - Antlerless/Spike | G88: Yes | H88: Yes | I88: 2026-09-01 | J88: See TPWD category page | K88: 10 | P88: 610 | Q88: Long Haul | R88: Research before draw; property brochure linked from TPWD | S88: Low | T88: No | U88: Verified in TPWD 2026-2027 statewide deer category catalog. | V88: https://tpwd.texas.gov/huntwild/hunt/public/public_hunt_drawing/hunt-category-details.phtml?OCat=PLA | W88: 2 | X88: 1 | Y88: 4 | Z88: 3 | AA88: 2 | AB88: 0 | AC88: 2.1 | AE88: 2026-09-01 | AM88: https://tpwd.texas.gov/huntwild/hunt/public/public_hunt_drawing/hunt-category-details.phtml?OCat=PLA | AN88: https://tpwd.texas.gov/search/?q=DeWitt+County+Ranch+public+hunting+brochure | AO88: https://apps.tpwd.state.tx.us/huntwild/hunt/public/public_hunt_drawing/ | AP88: https://www.google.com/maps/search/?api=1&query=DeWitt+County+Ranch%2C+Texas | AQ88: 0 | AR88: Standard Hastings ranking
A89: No | B89: A | C89: Whitetail Deer | D89: DeWitt County Ranch | E89: Houston / Gulf Coast | F89: Private Lands - Either Sex | G89: Yes | H89: Yes | I89: 2026-09-01 | J89: See TPWD category page | K89: 10 | P89: 610 | Q89: Long Haul | R89: Research before draw; property brochure linked from TPWD | S89: Low | T89: No | U89: Verified in TPWD 2026-2027 statewide deer category catalog. | V89: https://tpwd.texas.gov/huntwild/hunt/public/public_hunt_drawing/hunt-category-details.phtml?OCat=PLE | W89: 2 | X89: 1 | Y89: 4 | Z89: 3 | AA89: 2 | AB89: 0 | AC89: 2.1 | AE89: 2026-09-01 | AM89: https://tpwd.texas.gov/huntwild/hunt/public/public_hunt_drawing/hunt-category-details.phtml?OCat=PLE | AN89: https://tpwd.texas.gov/search/?q=DeWitt+County+Ranch+public+hunting+brochure | AO89: https://apps.tpwd.state.tx.us/huntwild/hunt/public/public_hunt_drawing/ | AP89: https://www.google.com/maps/search/?api=1&query=DeWitt+County+Ranch%2C+Texas | AQ89: 0 | AR89: Standard Hastings ranking
A90: No | B90: B | C90: Whitetail Deer | D90: Granger PHL | E90: Central Texas / Austin | F90: E-Postcard Archery Deer | G90: Yes | H90: Yes | I90: 2026-09-01 | J90: See TPWD category page | K90: 0 | L90: 0 | P90: 490 | Q90: Statewide | R90: Research before draw; property brochure linked from TPWD | S90: Low | T90: No | U90: Verified in TPWD 2026-2027 statewide deer category catalog. APH/eligibility rules apply; confirm account and permit requirements. V5 preference rule: Lower priority: archery whitetail is more than 200 miles from Amarillo. | V90: https://tpwd.texas.gov/huntwild/hunt/public/public_hunt_drawing/hunt-category-details.phtml?OCat=EAD | W90: 2 | X90: 2 | Y90: 4 | Z90: 3 | AA90: 2 | AB90: 0 | AC90: 1.3 | AD90: 0 | AE90: 2026-09-01 | AM90: https://tpwd.texas.gov/huntwild/hunt/public/public_hunt_drawing/hunt-category-details.phtml?OCat=EAD | AN90: https://tpwd.texas.gov/search/?q=Granger+PHL+public+hunting+brochure | AO90: https://apps.tpwd.state.tx.us/huntwild/hunt/public/public_hunt_drawing/ | AP90: https://www.google.com/maps/search/?api=1&query=Granger+PHL%2C+Texas | AQ90: -1 | AR90: Lower priority: archery whitetail is more than 200 miles from Amarillo
A91: No | B91: B | C91: Whitetail Deer | D91: Hagerman NWR | E91: North Texas / DFW | F91: National Refuge Archery Deer | G91: Yes | H91: Yes | I91: 2026-09-01 | J91: See TPWD category page | K91: 3 | P91: 360 | Q91: Extended | R91: Research before draw; property brochure linked from TPWD | S91: Low | T91: No | U91: Verified in TPWD 2026-2027 statewide deer category catalog. Refuge-specific rules and permit fees may apply. V5 preference rule: Lower priority: archery whitetail is more than 200 miles from Amarillo. | V91: https://tpwd.texas.gov/huntwild/hunt/public/public_hunt_drawing/hunt-category-details.phtml?OCat=NAD | W91: 2 | X91: 3 | Y91: 4 | Z91: 3 | AA91: 2 | AB91: 0 | AC91: 1.5 | AE91: 2026-09-01 | AM91: https://tpwd.texas.gov/huntwild/hunt/public/public_hunt_drawing/hunt-category-details.phtml?OCat=NAD | AN91: https://tpwd.texas.gov/search/?q=Hagerman+NWR+public+hunting+brochure | AO91: https://apps.tpwd.state.tx.us/huntwild/hunt/public/public_hunt_drawing/ | AP91: https://www.google.com/maps/search/?api=1&query=Hagerman+NWR%2C+Texas | AQ91: -1 | AR91: Lower priority: archery whitetail is more than 200 miles from Amarillo
A92: No | B92: B | C92: Whitetail Deer | D92: Keechi Creek WMA | E92: Statewide / Other | F92: E-Postcard Archery Deer | G92: Yes | H92: Yes | I92: 2026-09-01 | J92: See TPWD category page | K92: 0 | L92: 0 | P92: 500 | Q92: Statewide | R92: Research before draw; property brochure linked from TPWD | S92: Low | T92: No | U92: Verified in TPWD 2026-2027 statewide deer category catalog. APH/eligibility rules apply; confirm account and permit requirements. V5 preference rule: Lower priority: archery whitetail is more than 200 miles from Amarillo. | V92: https://tpwd.texas.gov/huntwild/hunt/public/public_hunt_drawing/hunt-category-details.phtml?OCat=EAD | W92: 2 | X92: 2 | Y92: 4 | Z92: 3 | AA92: 2 | AB92: 0 | AC92: 1.3 | AD92: 0 | AE92: 2026-09-01 | AM92: https://tpwd.texas.gov/huntwild/hunt/public/public_hunt_drawing/hunt-category-details.phtml?OCat=EAD | AN92: https://tpwd.texas.gov/search/?q=Keechi+Creek+WMA+public+hunting+brochure | AO92: https://apps.tpwd.state.tx.us/huntwild/hunt/public/public_hunt_drawing/ | AP92: https://www.google.com/maps/search/?api=1&query=Keechi+Creek+WMA%2C+Texas | AQ92: -1 | AR92: Lower priority: archery whitetail is more than 200 miles from Amarillo
...

Sheet Youth Priority
A1: Apply? | B1: Priority | C1: Species Group | D1: Hunt Area | E1: Hunt Category | F1: Deadline | G1: Approx Miles | H1: Draw Odds | I1: Permits | J1: Applicants | K1: Notes | L1: Source URL
A2: No | B2: A | C2: Mule Deer | D2: Big Bend Ranch SP | E2: Archery Mule Deer | F2: 2026-08-15 | G2: 520 | K2: Verified in TPWD 2026-2027 statewide deer category catalog. West Texas/El Paso-region opportunity; prioritize for mule deer adventure value. | L2: https://tpwd.texas.gov/huntwild/hunt/public/public_hunt_drawing/hunt-category-details.phtml?OCat=AMD
A3: No | B3: A | C3: Mule Deer | D3: Black Gap WMA | E3: Archery Mule Deer | F3: 2026-08-15 | G3: 520 | K3: Verified in TPWD 2026-2027 statewide deer category catalog. West Texas/El Paso-region opportunity; prioritize for mule deer adventure value. | L3: https://tpwd.texas.gov/huntwild/hunt/public/public_hunt_drawing/hunt-category-details.phtml?OCat=AMD
A4: No | B4: A | C4: Mule Deer | D4: Elephant Mountain WMA | E4: Archery Mule Deer | F4: 2026-08-15 | G4: 520 | K4: Verified in TPWD 2026-2027 statewide deer category catalog. West Texas/El Paso-region opportunity; prioritize for mule deer adventure value. | L4: https://tpwd.texas.gov/huntwild/hunt/public/public_hunt_drawing/hunt-category-details.phtml?OCat=AMD
A5: No | B5: A | C5: Mule Deer | D5: Matador WMA | E5: Archery Mule Deer | F5: 2026-08-15 | G5: 130 | K5: Verified in TPWD 2026-2027 statewide deer category catalog. | L5: https://tpwd.texas.gov/huntwild/hunt/public/public_hunt_drawing/hunt-category-details.phtml?OCat=AMD
A6: No | B6: A | C6: Mule Deer | D6: Potter County - Cross Bar Mgt. Area | E6: Archery Mule Deer | F6: 2026-08-15 | G6: 130 | K6: Verified in TPWD 2026-2027 statewide deer category catalog. | L6: https://tpwd.texas.gov/huntwild/hunt/public/public_hunt_drawing/hunt-category-details.phtml?OCat=AMD
A7: No | B7: A | C7: Whitetail Deer | D7: Abilene SP | E7: Archery Deer | F7: 2026-08-15 | G7: 300 | K7: Verified in TPWD 2026-2027 statewide deer category catalog. | L7: https://tpwd.texas.gov/huntwild/hunt/public/public_hunt_drawing/hunt-category-details.phtml?OCat=ADE
A8: No | B8: A | C8: Whitetail Deer | D8: Chaparral WMA | E8: Archery Deer | F8: 2026-08-15 | G8: 700 | K8: Verified in TPWD 2026-2027 statewide deer category catalog. | L8: https://tpwd.texas.gov/huntwild/hunt/public/public_hunt_drawing/hunt-category-details.phtml?OCat=ADE
A9: No | B9: A | C9: Whitetail Deer | D9: Choke Canyon SP - North Shore Unit | E9: Archery Deer | F9: 2026-08-15 | G9: 700 | K9: Verified in TPWD 2026-2027 statewide deer category catalog. | L9: https://tpwd.texas.gov/huntwild/hunt/public/public_hunt_drawing/hunt-category-details.phtml?OCat=ADE
A10: No | B10: A | C10: Whitetail Deer | D10: Colorado Bend SP | E10: Archery Deer | F10: 2026-08-15 | G10: 490 | K10: Verified in TPWD 2026-2027 statewide deer category catalog. | L10: https://tpwd.texas.gov/huntwild/hunt/public/public_hunt_drawing/hunt-category-details.phtml?OCat=ADE
A11: No | B11: A | C11: Whitetail Deer | D11: Copper Breaks SP | E11: Archery Deer | F11: 2026-08-15 | G11: 300 | K11: Verified in TPWD 2026-2027 statewide deer category catalog. | L11: https://tpwd.texas.gov/huntwild/hunt/public/public_hunt_drawing/hunt-category-details.phtml?OCat=ADE
A12: No | B12: A | C12: Whitetail Deer | D12: Enchanted Rock SNA | E12: Archery Deer | F12: 2026-08-15 | G12: 520 | K12: Verified in TPWD 2026-2027 statewide deer category catalog. | L12: https://tpwd.texas.gov/huntwild/hunt/public/public_hunt_drawing/hunt-category-details.phtml?OCat=ADE
A13: No | B13: A | C13: Whitetail Deer | D13: Fort Boggy SP | E13: Archery Deer | F13: 2026-08-15 | G13: 360 | K13: Verified in TPWD 2026-2027 statewide deer category catalog. | L13: https://tpwd.texas.gov/huntwild/hunt/public/public_hunt_drawing/hunt-category-details.phtml?OCat=ADE
... A265: No | B265: A | C265: Whitetail Deer | D265: Trinity River NWR - Page | E265: National Refuge Muzzleloader Deer | F265: 2026-10-15 | G265: 570 | K265: Verified in TPWD 2026-2027 statewide deer category catalog. Refuge-specific rules and permit fees may apply. | L265: https://tpwd.texas.gov/huntwild/hunt/public/public_hunt_drawing/hunt-category-details.phtml?OCat=NMD

Sheet Application Calendar
A1: Deadline | B1: Main Categories to Apply | C1: Suggested Action | D1: Estimated App Fees in Master | E1: Notes
A2: 2026-08-15 | B2: Archery Deer, Archery Mule Deer, Pronghorn, USFS/E-Postcard openers | C2: Submit all August 15 items first | D2: =SUMIFS('Master Hunt List'!K:K,'Master Hunt List'!I:I,A2) -> 107 | E2: E-postcard requires APH; pronghorn/private lands are early.
A3: 2026-09-01 | B3: National Wildlife Refuge hunts | C3: Check Buffalo Lake and Muleshoe refuge options | D3: =SUMIFS('Master Hunt List'!K:K,'Master Hunt List'!I:I,A3) -> 152 | E3: Some NWR hunts have separate rules.
A4: 2026-09-15 | B4: Deer: youth, antlerless/spike, either-sex, management | C4: Do not miss youth deer and core Panhandle deer | D4: =SUMIFS('Master Hunt List'!K:K,'Master Hunt List'!I:I,A4) -> 273 | E4: This is the big deer deadline.
A5: 2026-10-01 | B5: Mule deer/private quail/turkey varies | C5: Check mule deer and upland items | D5: =SUMIFS('Master Hunt List'!K:K,'Master Hunt List'!I:I,A5) -> 46 | E5: Some dates vary by category.
A6: 2026-10-15 | B6: Late deer/exotics/e-postcards varies | C6: Sweep remaining fall hunts | D6: =SUMIFS('Master Hunt List'!K:K,'Master Hunt List'!I:I,A6) -> 18 | E6: Verify remaining TPWD pages.
A7: 2026-11-01 | B7: Feral Hog / Youth Feral Hog | C7: Apply for hogs after deer applications are done | D7: =SUMIFS('Master Hunt List'!K:K,'Master Hunt List'!I:I,A7) -> 15 | E7: Great winter family hunting opportunities.
A8: 2027-01-15 | B8: Spring Turkey / Youth Spring Turkey | C8: Apply for spring turkey | D8: =SUMIFS('Master Hunt List'!K:K,'Master Hunt List'!I:I,A8) -> 6 | E8: Good season extender.

Sheet Draw Odds
A1: Hunt Area | B1: Hunt Category | C1: Species | D1: Applicants Last Year | E1: Permits/Groups | F1: Draw Odds | G1: Odds Tier | H1: Source URL
A2: Gene Howe WMA | B2: Feral Hog | C2: Feral Hog | D2: 344 | E2: 6 | F2: 0.33 | G2: Good | H2: https://tpwd.texas.gov/huntwild/hunt/public/public_hunt_drawing/hunt-category-details.phtml?OCat=GFH
A3: Matador WMA | B3: Youth Only Feral Hog | C3: Feral Hog | D3: 347 | E3: 26 | F3: 0.18 | G3: Fair | H3: https://tpwd.texas.gov/huntwild/hunt/public/public_hunt_drawing/hunt-category-details.phtml?OCat=YFH
A4: Fort Boggy SP | B4: Feral Hog | C4: Feral Hog | D4: 296 | E4: 5 | F4: 0.2 | G4: Fair | H4: https://tpwd.texas.gov/huntwild/hunt/public/public_hunt_drawing/hunt-category-details.phtml?OCat=GFH
A5: Justin Hurst WMA | B5: Youth Only Feral Hog | C5: Feral Hog | D5: 529 | E5: 30 | F5: 0.62 | G5: High | H5: https://tpwd.texas.gov/huntwild/hunt/public/public_hunt_drawing/hunt-category-details.phtml?OCat=YFH

Sheet Budget Planner
A1: Hastings Family Draw Budget Planner
A2: Input | B2: Value | C2: Formula/Notes
A3: Fuel cost per mile | B3: 0.22 | C3: Change this to match your van/trailer gas estimate
A4: Camping/lodging per night | B4: 25 | C4: Enter your average camp cost
A5: Average nights per drawn hunt | B5: 3 | C5: Change per your family plan
A7: Summary | B7: Formula | C7: Value
A8: Applied application fees | B8: =SUMIF('Master Hunt List'!A:A,"Yes",'Master Hunt List'!K:K) -> 0
A9: Potential permit fees if all applied draw | B9: =SUMIF('Master Hunt List'!A:A,"Yes",'Master Hunt List'!L:L) -> 0
A10: Estimated fuel if all applied draw | B10: =SUMIF('Master Hunt List'!A:A,"Yes",'Master Hunt List'!P:P)*2*$B$3 -> 0
A11: Estimated camping if all applied draw | B11: =COUNTIF('Master Hunt List'!A:A,"Yes")*$B$4*$B$5 -> 0
A12: Total estimated cost if all applied draw | B12: =SUM(B8:B11) -> 0

Sheet Hastings Hunt History
A1: Year | B1: Hunt Area | C1: Species | D1: Hunt Type | E1: Drawn? | F1: Harvest? | G1: Camped? | H1: Backpack? | I1: Notes
A2: 2025 | B2: Caprock Canyons SP | C2: Mule Deer | D2: Youth Caprock Canyon | E2: Yes | G2: Yes | I2: User reported drawn last year.
A3: 2025 | B3: Lake McClellan | C3: Whitetail Deer | D3: Youth Lake McClellan | E3: Yes | G3: Yes | I3: User reported drawn last year.
A4: 2025 | B4: Potter County Cross Bar | C4: Whitetail Deer | D4: Whitetail Management | E4: Yes | G4: Yes | H4: Yes | I4: User reported drawn; prior context says Cross Bar backpack hunt.

Sheet Whitetail Deer
A1: Applied | B1: Priority | C1: Species Group | D1: Hunt Area | E1: Region | F1: Hunt Category | G1: Adult | H1: Youth | I1: Application Deadline | J1: Hunt Window | K1: Application Fee | L1: Estimated Permit Fee | M1: Permits/Groups | N1: Applicants Last Year | O1: Draw Odds | P1: Approx Miles from Amarillo | Q1: Drive Zone | R1: Camping Notes | S1: Backpack Rating | T1: Past Drawn by Hastings | U1: Notes | V1: Source URL | W1: Odds Score | X1: Distance Score | Y1: Youth Fit Score | Z1: Camping Score | AA1: Backpack Score | AB1: Past Draw Bonus | AC1: Hastings Score | AD1: Estimated Total If Drawn | AE1: Deadline Month | AF1: Applicant(s) | AG1: Date Applied | AH1: TPWD Confirmation # | AI1: Draw Status | AJ1: Draw Result Date | AK1: Harvest/Outcome | AL1: Post-Hunt Notes | AM1: Official Category Link | AN1: TPWD Area / Brochure Search | AO1: TPWD Apply Portal | AP1: Google Maps | AQ1: Preference Adjustment | AR1: Priority Reason
A2: No | B2: B | C2: Whitetail Deer | D2: Abilene SP | E2: West-Central Texas | F2: Archery Deer | G2: Yes | H2: Yes | I2: 2026-08-15 | J2: See TPWD category page | K2: 3 | P2: 300 | Q2: Extended | R2: Research before draw; property brochure linked from TPWD | S2: Low | T2: No | U2: Verified in TPWD 2026-2027 statewide deer category catalog. V5 preference rule: Lower priority: archery whitetail is more than 200 miles from Amarillo. | V2: https://tpwd.texas.gov/huntwild/hunt/public/public_hunt_drawing/hunt-category-details.phtml?OCat=ADE | W2: 2 | X2: 4 | Y2: 4 | Z2: 3 | AA2: 2 | AB2: 0 | AC2: 1.6 | AE2: 2026-08-15 | AM2: https://tpwd.texas.gov/huntwild/hunt/public/public_hunt_drawing/hunt-category-details.phtml?OCat=ADE | AN2: https://tpwd.texas.gov/search/?q=Abilene+SP+public+hunting+brochure | AO2: https://apps.tpwd.state.tx.us/huntwild/hunt/public/public_hunt_drawing/ | AP2: https://www.google.com/maps/search/?api=1&query=Abilene+SP%2C+Texas | AQ2: -1 | AR2: Lower priority: archery whitetail is more than 200 miles from Amarillo
